---
layout:     post
title:      JavaEE
subtitle:   异常
date:       2021-10-09
author:     Uarealoser
header-img: img/post-bg-ios9-web.jpg
catalog: true
tags:
    - java
---

# 异常处理机制

```
try{
    // ...
}catch(Exception e){
    // ...
}
```

如果执行try块里的业务代码时出现异常，系统自动生成一个异常对象，该异常对象被提交给Java运行时环境，这个过程被称为抛出异常。

当java运行时环境收到异常对象后，会寻找能处理该异常对象的catch块，如果找到合适的catch块，则把该异常交给catch块处理，这个过程称为捕获异常。如果java运行时环境找不到捕获异常的catch块，则运行时环境终止，java程序也将退出。

## 异常类的继承体系

java是如何为该异常对象寻找catch块的呢？

catch块后的Exception类表示每个catch块专门用于处理*异常类及其子类*的异常实例。java运行时拿到异常对象后，会依次从上到下寻找匹配的catch块。

*java把所有的非正常情况分为2种:异常(Exception)和错误(Error),它们都继承自Thrownable父类。*

Error错误说明:一般指虚拟机相关的问题，如系统崩溃，虚拟机错误，动态链接失败等。这种错误无法修复或不能捕获，将导致程序异常中断。应用程序通常不应该试图通过catch块捕获Error对象。

## 访问异常信息

所有的异常对象一般都包含如下方法：

- getMessage():返回异常详细描述字符串
- printStackTrace():将该异常的跟踪栈信息输出到标准错误中。
- printStackTrace(PrintStream s):将该异常的跟踪栈信息输出到指定输出流。
- getStackTrace():返回该异常的跟踪栈信息。

## finally

在java中，可以使用finally来进行资源回收，原因是:

大多数情况下，fianlly块总能获得执行机会，即使在try，catch块中使用了return语句。除非，在try，catch块中使用了System.exit(1)或其他命令来使程序退出虚拟机，则finally块将无法获得执行机会。

*注意*:不要在fianlly块中使用return或throw语句等可以让方法返回的语句。一旦在finally块中使用了return或throw语句，将会导致try，catch块的return，throw语句失效。

## 异常处理的嵌套

在try，catch，finally块中使用再次使用完整的异常处理流程的情况被称为异常处理嵌套。异常处理的深度并没有很明确的限制，但通常没有必要使用超过两层的异常处理嵌套。

## 自动关闭资源try

try可以紧跟一对圆括号，圆括号可以声明，初始化一个或多个资源(指哪些需要显示关闭的资源)，try语句在该语句结束时，将自动关闭这些资源。

需要指出的是，为了保证try语句可以正常关闭资源，这些资源的实现类必须实现AutoCloseable或Colseable接口，并实现其close方法。

```
    public static void main(String[] args) {
        try(
                BufferedReader bufferedReader = new BufferedReader(new FileReader("a.txt"));
                PrintStream printStream = new PrintStream(new FileOutputStream("a.txt"));
        ){
            bufferedReader.readLine();
            printStream.print("helloworld");

        } catch (FileNotFoundException e) {
            e.printStackTrace();
        } catch (IOException e) {
            e.printStackTrace();
        }
    }
```

## Checked异常与Runtime异常

Java的异常体系被分为2大类:Check异常和Runtime异常(运行时异常)，所有的RuntimeException类及其子类的实例被称为Runtime异常；不是RuntimeException类及其子类的异常实例则被称为Checked异常。

> 只有Java语言提供了Checked异常，其他语言很多并没有。java认为Checked异常是可以被处理的异常，所以Java程序必须显示的处理Checked异常。如果程序没有处理Checked异常，该程序在编译期间便会出错。

对于Checked异常的处理方式:

- 使用try catch进行捕获 处理
- 向上抛出

## throws

使用thorws声明抛出异常:当前方法不知道如何处理这类异常，该异常应该由上一级调用者处理；如果main方法也不知道如何处理这种异常，也可以使用throws声明抛出异常，将异常交给JVM处理。JVM对异常的处理方式就是:打印异常的跟踪栈信息，并中止程序的运行。

用户可以在方法签名后使用throws关键字来抛出多个异常，用逗号分割。且一旦使用throws语句声明抛出异常，程序就无法使用try catch块来捕获该异常了。

Checked异常使用的两大不便之处:

- 对于程序中的Checked异常，Java要求必须显式的捕获并处理异常，或者显示声明抛出该异常。
- 如果方法中显示声明抛出异常，将会导致方法签名与异常耦合。特别是如果方法是重写的父类方法，则抛出的异常还会受到被重写方法抛出异常的限制(子类方法声明抛出的异常类型应该是父类方法声明抛出的异常类型的子类或同一个类，子类抛出的异常不允许比父类方法抛出的异常多)

因此，当我们的程序需要使用throws自行抛出异常时，更应该抛出Runtime异常。这样，程序同样只需要在合适的地方捕获并对应异常进行处理。但是，抛出Checked异常，也有自己的好处，可以提醒用户去处理异常。

## throw

当程序需要抛出异常时，可以使用throw关键字抛出异常实例(不是异常类)，而且每次只能抛出一个异常实例。

```
public class CatchExceptionDemo {
    public static void main(String[] args) throws InterruptedException {
        new Thread(()->{
            System.out.println("before throwChecked");
            // 调用抛出Checked异常方法
            try {
                throwChecked(1);
                System.out.println("after throwChecked");
            } catch (Exception e) {
                System.out.println("catch throwChecked");
            }
        }).start();

        new Thread(()->{
                System.out.println("before throwRuntime");
                // 调用抛出Runtime 异常方法, 可以不用理会
                throwRuntime(1);
                System.out.println("after throwRuntime");

        }).start();
        TimeUnit.SECONDS.sleep(10);
    }

    public static void throwChecked(int a) throws Exception{
        if (a>0){
            throw new Exception("a>0");
        }
    }

    public static void throwRuntime(int a){
        if (a>0){
            throw new RuntimeException("a>0");
        }
    }
}

// 输出:
before throwChecked
catch throwChecked
before throwRuntime
Exception in thread "Thread-1" java.lang.RuntimeException: a>0
	at com.ual.javalab.practicemakesperfect.d8.CatchExceptionDemo.throwRuntime(CatchExceptionDemo.java:36)
	at com.ual.javalab.practicemakesperfect.d8.CatchExceptionDemo.lambda$main$1(CatchExceptionDemo.java:21)
	at java.lang.Thread.run(Thread.java:748)
```

## 自定义异常类

异常的类名通常也包含了该异常的游泳信息。因此在选择抛出异常时，应该选择合适的异常类，从而明确描述异常情况。在这种情况下，用户通常需要自定义异常。

- 用户定义自定义异常都应该继承Exception基类，如果希望自定义Runtime异常，则应该继承RuntimeException积累。
- 定义异常类时，通常需要提供两个构造器，一个是无参构造器，另一个是带字符串的构造器，这个字符串作为该异常对象的描述信息，即getMessage()返回的内容。

```
public class MyException extends Exception{
    // 无参构造器
    public MyException(){}
    
    //带字符串构造器
    public MyException(String msg){
        super(msg);
    }
}
```

## 使用异常时应该注意的点

- 不要过度使用异常
    只抛出不处理，使用异常处理来代替流程处理
- 使用过于庞大的try块
    大量代码放在一个try块中，会造成try块中出现异常的可能性大大增加，从而导致分析异常原因的难度也增大。正确的做法应该是把大块的try块分割成多个可能出现异常的程序段落，并把它们放在单独的try块中分别捕获。